<?xml version="1.0" ?>
<!-- =================================================================================== -->
<!-- |    This document was autogenerated by xacro from ./src/z1_description/urdf/z1.xacro | -->
<!-- |    EDITING THIS FILE BY HAND IS NOT RECOMMENDED                                 | -->
<!-- =================================================================================== -->
<robot name="z1">
  <link name="world"/>
  <link name="base"/>
  <joint name="base_static_joint" type="fixed">
    <origin rpy="0 0 0" xyz="0 0 0"/>
    <parent link="world"/>
    <child link="base"/>
  </joint>
  <joint name="base_joint" type="fixed">
    <parent link="base"/>
    <child link="link00"/>
    <origin rpy="0 0 0" xyz="0 0.0 0.0"/>
  </joint>
  <link name="link00">
    <visual>
      <origin rpy="0 0 0" xyz="0 0 0"/>
      <geometry>
        <mesh filename="file:///home/ccs/ROS2/learn_ws/src/z1_description/meshes/z1_Link00.dae" scale="1 1 1"/>
      </geometry>
    </visual>
    <collision>
      <geometry>
        <cylinder length="0.051" radius="0.0325"/>
      </geometry>
      <origin rpy="0 0 0" xyz="0 0 0.0255"/>
    </collision>
    <inertial>
      <origin rpy="0 0 0" xyz="-0.00334984 -0.00013615 0.02495843"/>
      <mass value="0.47247481"/>
      <inertia ixx="0.00037937" ixy="3.5e-07" ixz="1.037e-05" iyy="0.00041521" iyz="9.9e-07" izz="0.00053066"/>
    </inertial>
  </link>
  <joint name="joint1" type="revolute">
    <origin rpy="0 0 0" xyz="0 0 0.0585"/>
    <parent link="link00"/>
    <child link="link01"/>
    <axis xyz="0 0 1"/>
    <dynamics damping="0.0" friction="0.0"/>
    <limit effort="30.0" lower="-2.6179938779914944" upper="2.6179938779914944" velocity="10"/>
  </joint>
  <link name="link01">
    <visual>
      <origin rpy="0 0 0" xyz="0 0 0"/>
      <geometry>
        <mesh filename="file:///home/ccs/ROS2/learn_ws/src/z1_description/meshes/z1_Link01.dae" scale="1 1 1"/>
      </geometry>
    </visual>
    <collision>
      <geometry>
        <cylinder length="0.102" radius="0.0325"/>
      </geometry>
      <origin rpy="0 0 0" xyz="0 0 0"/>
    </collision>
    <inertial>
      <origin rpy="0 0 0" xyz="2.47e-06 -0.00025198 0.02317169"/>
      <mass value="0.67332551"/>
      <inertia ixx="0.00128328" ixy="6e-08" ixz="4e-07" iyy="0.00071931" iyz="-5e-07" izz="0.00083936"/>
    </inertial>
  </link>
  <joint name="joint2" type="revolute">
    <origin rpy="0 0 0" xyz="0 0 0.045"/>
    <parent link="link01"/>
    <child link="link02"/>
    <axis xyz="0 1 0"/>
    <dynamics damping="0.0" friction="0.0"/>
    <limit effort="60.0" lower="0.0" upper="3.141592653589793" velocity="10"/>
  </joint>
  <link name="link02">
    <visual>
      <origin rpy="0 0 0" xyz="0 0 0"/>
      <geometry>
        <mesh filename="file:///home/ccs/ROS2/learn_ws/src/z1_description/meshes/z1_Link02.dae" scale="1 1 1"/>
      </geometry>
    </visual>
    <collision>
      <geometry>
        <cylinder length="0.102" radius="0.0325"/>
      </geometry>
      <origin rpy="1.5707963267948966 0 0" xyz="0 0 0"/>
    </collision>
    <collision>
      <geometry>
        <cylinder length="0.235" radius="0.0225"/>
      </geometry>
      <origin rpy="0 1.5707963267948966 0" xyz="-0.16249999999999998 0 0"/>
    </collision>
    <collision>
      <geometry>
        <cylinder length="0.051" radius="0.0325"/>
      </geometry>
      <origin rpy="1.5707963267948966 0 0" xyz="-0.35 0 0"/>
    </collision>
    <inertial>
      <origin rpy="0 0 0" xyz="-0.11012601 0.00240029 0.00158266"/>
      <mass value="1.19132258"/>
      <inertia ixx="0.00102138" ixy="-0.00062358" ixz="-5.13e-06" iyy="0.02429457" iyz="2.1e-06" izz="0.02466114"/>
    </inertial>
  </link>
  <joint name="joint3" type="revolute">
    <origin rpy="0 0 0" xyz="-0.35 0 0"/>
    <parent link="link02"/>
    <child link="link03"/>
    <axis xyz="0 1 0"/>
    <dynamics damping="0.0" friction="0.0"/>
    <limit effort="30.0" lower="-4.782202150464463" upper="0.0" velocity="10"/>
  </joint>
  <link name="link03">
    <visual>
      <origin rpy="0 0 0" xyz="0 0 0"/>
      <geometry>
        <mesh filename="file:///home/ccs/ROS2/learn_ws/src/z1_description/meshes/z1_Link03.dae" scale="1 1 1"/>
      </geometry>
    </visual>
    <collision>
      <geometry>
        <cylinder length="0.116" radius="0.02"/>
      </geometry>
      <origin rpy="0 1.5707963267948966 0" xyz="0.128 0 0.055"/>
    </collision>
    <collision>
      <geometry>
        <cylinder length="0.059" radius="0.0325"/>
      </geometry>
      <origin rpy="0 1.5707963267948966 0" xyz="0.2205 0 0.055"/>
    </collision>
    <inertial>
      <origin rpy="0 0 0" xyz="0.10609208 -0.00541815 0.03476383"/>
      <mass value="0.83940874"/>
      <inertia ixx="0.00108061" ixy="8.669e-05" ixz="0.00208102" iyy="0.00954238" iyz="1.332e-05" izz="0.00886621"/>
    </inertial>
  </link>
  <joint name="joint4" type="revolute">
    <origin rpy="0 0 0" xyz="0.218 0 0.057"/>
    <parent link="link03"/>
    <child link="link04"/>
    <axis xyz="0 1 0"/>
    <dynamics damping="0.0" friction="0.0"/>
    <limit effort="30.0" lower="-1.7453292519943295" upper="1.5707963267948966" velocity="10"/>
  </joint>
  <link name="link04">
    <visual>
      <origin rpy="0 0 0" xyz="0 0 0"/>
      <geometry>
        <mesh filename="file:///home/ccs/ROS2/learn_ws/src/z1_description/meshes/z1_Link04.dae" scale="1 1 1"/>
      </geometry>
    </visual>
    <collision>
      <geometry>
        <cylinder length="0.073" radius="0.0325"/>
      </geometry>
      <origin rpy="1.5707963267948966 0 0" xyz="0.0472 0 0"/>
    </collision>
    <inertial>
      <origin rpy="0 0 0" xyz="0.04366681 0.00364738 -0.00170192"/>
      <mass value="0.56404563"/>
      <inertia ixx="0.00031576" ixy="-8.13e-05" ixz="-4.091e-05" iyy="0.00092996" iyz="5.96e-06" izz="0.00097912"/>
    </inertial>
  </link>
  <joint name="joint5" type="revolute">
    <origin rpy="0 0 0" xyz="0.07 0.0 0.0"/>
    <parent link="link04"/>
    <child link="link05"/>
    <axis xyz="0 0 1"/>
    <dynamics damping="0.0" friction="0.0"/>
    <limit effort="30.0" lower="-1.7278759594743864" upper="1.7278759594743864" velocity="10"/>
  </joint>
  <link name="link05">
    <visual>
      <origin rpy="0 0 0" xyz="0 0 0"/>
      <geometry>
        <mesh filename="file:///home/ccs/ROS2/learn_ws/src/z1_description/meshes/z1_Link05.dae" scale="1 1 1"/>
      </geometry>
    </visual>
    <inertial>
      <origin rpy="0 0 0" xyz="0.03121533 0.0 0.00646316"/>
      <mass value="0.38938492"/>
      <inertia ixx="0.00017605" ixy="-4e-07" ixz="-5.689e-05" iyy="0.00055896" iyz="1.3e-07" izz="0.0005386"/>
    </inertial>
  </link>
  <joint name="joint6" type="revolute">
    <origin rpy="0 0 0" xyz="0.0492 0.0 0.0"/>
    <parent link="link05"/>
    <child link="link06"/>
    <axis xyz="1 0 0"/>
    <dynamics damping="0.0" friction="0.0"/>
    <limit effort="30.0" lower="-2.792526803190927" upper="2.792526803190927" velocity="10"/>
  </joint>
  <link name="link06">
    <visual>
      <origin rpy="0 0 0" xyz="0 0 0"/>
      <geometry>
        <mesh filename="file:///home/ccs/ROS2/learn_ws/src/z1_description/meshes/z1_Link06.dae" scale="1 1 1"/>
      </geometry>
    </visual>
    <collision>
      <geometry>
        <cylinder length="0.051" radius="0.0325"/>
      </geometry>
      <origin rpy="0 1.5707963267948966 0" xyz="0.0255 0 0"/>
    </collision>
    <inertial>
      <origin rpy="0 0 0" xyz="0.0241569 -0.00017355 -0.00143876"/>
      <mass value="0.28875807"/>
      <inertia ixx="0.00018328" ixy="-1.22e-06" ixz="-5.4e-07" iyy="0.0001475" iyz="-8e-08" izz="0.0001468"/>
    </inertial>
  </link>
  <joint name="joint7" type="fixed">
    <!-- <origin rpy="-${pi/2} 0.0 -${pi/2}" xyz="0.051 0.0 0.0"/> -->
    <origin rpy="1.5707963267948966 0.0 1.5707963267948966" xyz="0.051 0.0 0.0"/>
    <parent link="link06"/>
    <child link="link07"/>
    <axis xyz="0 0 0"/>
  </joint>
  <link name="link07">
        </link>
  <joint name="camera_joint" type="fixed">
    <parent link="link06"/>
    <child link="camera_link"/>
    <origin rpy="0 0 0" xyz="0.071 0 0.08"/>
  </joint>
  <!-- device Center -->
  <link name="camera_link">
    <visual>
      <origin rpy="0 0 0" xyz="0 0 0"/>
      <geometry>
        <mesh filename="file:///home/ccs/ROS2/learn_ws/src/z1_description/meshes/OAK-D-LITE.dae"/>
      </geometry>
    </visual>
    <collision>
      <geometry>
        <mesh filename="file:///home/ccs/ROS2/learn_ws/src/z1_description/meshes/OAK-D-LITE.dae"/>
      </geometry>
      <origin rpy="0 0 0" xyz="0 0 0"/>
    </collision>
  </link>
  <!-- RGB Camera -->
  <link name="camera_rgb_frame"/>
  <joint name="camera_rgb_frame_joint" type="fixed">
    <parent link="camera_link"/>
    <child link="camera_rgb_frame"/>
    <origin rpy="0 0 0" xyz="0 0 0"/>
  </joint>
  <link name="camera_rgb_optical_frame"/>
  <joint name="camera_rgb_optical_frame_joint" type="fixed">
    <origin rpy="-1.5707963267948966 0.0 -1.5707963267948966" xyz="0 0 0"/>
    <parent link="camera_rgb_frame"/>
    <child link="camera_rgb_optical_frame"/>
  </joint>
  <gazebo reference="camera_rgb_frame">
    <!-- 这个sensor代表的link -->
    <sensor name="oak_d_lite" type="rgbd_camera">
      <update_rate>60.0</update_rate>
      <camera>
        <horizontal_fov>1.047198</horizontal_fov>
        <image>
          <width>320</width>
          <height>240</height>
          <!-- <format>R8G8B8</format> -->
        </image>
        <!-- <clip>
                        <near>0.1</near>
                        <far>100</far>
                    </clip>
                    <noise>
                        <type>gaussian</type>
                        <mean>0.0</mean>
                        <stddev>0.007</stddev>
                    </noise> -->
        <!-- <always_on>1</always_on> -->
        <!-- <update_rate>30</update_rate> -->
        <!-- <visualize>true</visualize> -->
        <!-- <topic>rgbd_camera</topic> -->
        <!-- <enable_metrics>true</enable_metrics> -->
        <!-- <frameName>${id}camera_rgb_frame</frameName> -->
      </camera>
    </sensor>
  </gazebo>
  <link name="ft_link">
    <visual>
      <geometry>
        <cylinder length="0.04" radius="0.025"/>
      </geometry>
      <origin rpy="0 0.0 0.0" xyz="0.0 0.0 0.0"/>
    </visual>
    <collision>
      <geometry>
        <cylinder length="0.04" radius="0.025"/>
      </geometry>
      <origin rpy="0 0.0 0.0" xyz="0.0 0.0 0.0"/>
    </collision>
    <inertial>
      <mass value="0.03"/>
      <inertia ixx="8.687496525000001e-06" ixy="0.0" ixz="0.0" iyy="8.687496525000001e-06" iyz="0.0" izz="9.375000000000001e-06"/>
    </inertial>
  </link>
  <gazebo reference="ft_link">
    <collision>
      <max_contacts>10</max_contacts>
      <surface>
        <friction>
          <ode>
            <mu>1.0</mu>
            <mu2>1.0</mu2>
          </ode>
        </friction>
        <contact>
          <ode>
            <kp>10000000.0</kp>
            <kd>1.0</kd>
            <min_depth>0.001</min_depth>
            <max_vel>0.1</max_vel>
          </ode>
        </contact>
      </surface>
    </collision>
    <turnGravityOff>false</turnGravityOff>
  </gazebo>
  <joint name="ft_joint" type="fixed">
    <origin rpy="1.5707963267948966 0.0 1.5707963267948966" xyz="0.071 0.0 0.0"/>
    <parent link="link06"/>
    <child link="ft_link"/>
  </joint>
  <!-- Enable the Joint Feedback -->
  <gazebo reference="ft_joint">
    <preserveFixedJoint>true</preserveFixedJoint>
    <!-- <provide_feedback>true</provide_feedback> -->
    <disableFixedJointLumping>true</disableFixedJointLumping>
    <sensor name="ft_sensor" type="force_torque">
      <update_rate>200</update_rate>
      <!-- <enable_metrics>true</enable_metrics> -->
      <force_torque>
        <frame>child</frame>
        <measure_direction>child_to_parent</measure_direction>
        <force>
          <x>
            <noise type="gaussian">
              <mean>0</mean>
              <stddev>0.0</stddev>
              <bias_mean>0</bias_mean>
              <bias_stddev>0</bias_stddev>
              <dynamic_bias_stddev>0</dynamic_bias_stddev>
              <dynamic_bias_correlation_time>0</dynamic_bias_correlation_time>
              <precision>0</precision>
            </noise>
          </x>
          <y>
            <noise type="gaussian">
              <mean>0</mean>
              <stddev>0.0</stddev>
              <bias_mean>0</bias_mean>
              <bias_stddev>0</bias_stddev>
              <dynamic_bias_stddev>0</dynamic_bias_stddev>
              <dynamic_bias_correlation_time>0</dynamic_bias_correlation_time>
              <precision>0</precision>
            </noise>
          </y>
          <z>
            <noise type="gaussian">
              <mean>0</mean>
              <stddev>0.0</stddev>
              <bias_mean>0</bias_mean>
              <bias_stddev>0</bias_stddev>
              <dynamic_bias_stddev>0</dynamic_bias_stddev>
              <dynamic_bias_correlation_time>0</dynamic_bias_correlation_time>
              <precision>0</precision>
            </noise>
          </z>
        </force>
        <torque>
          <x>
            <noise type="gaussian">
              <mean>0</mean>
              <stddev>0.000</stddev>
              <bias_mean>0</bias_mean>
              <bias_stddev>0</bias_stddev>
              <dynamic_bias_stddev>0</dynamic_bias_stddev>
              <dynamic_bias_correlation_time>0</dynamic_bias_correlation_time>
              <precision>0</precision>
            </noise>
          </x>
          <y>
            <noise type="gaussian">
              <mean>0</mean>
              <stddev>0.000</stddev>
              <bias_mean>0</bias_mean>
              <bias_stddev>0</bias_stddev>
              <dynamic_bias_stddev>0</dynamic_bias_stddev>
              <dynamic_bias_correlation_time>0</dynamic_bias_correlation_time>
              <precision>0</precision>
            </noise>
          </y>
          <z>
            <noise type="gaussian">
              <mean>0</mean>
              <stddev>0.000</stddev>
              <bias_mean>0</bias_mean>
              <bias_stddev>0</bias_stddev>
              <dynamic_bias_stddev>0</dynamic_bias_stddev>
              <dynamic_bias_correlation_time>0</dynamic_bias_correlation_time>
              <precision>0</precision>
            </noise>
          </z>
        </torque>
      </force_torque>
    </sensor>
  </gazebo>
  <ros2_control name="GazeboSimSystem" type="system">
    <hardware>
      <plugin>gz_ros2_control/GazeboSimSystem</plugin>
    </hardware>
    <joint name="joint1">
      <command_interface name="position">
        <param name="min">{-2*pi}</param>
        <param name="max">{2*pi}</param>
      </command_interface>
      <command_interface name="velocity">
        <param name="min">-3.2</param>
        <param name="max">3.2</param>
      </command_interface>
      <command_interface name="effort">
        <param name="min">-30</param>
        <param name="max">30</param>
      </command_interface>
      <state_interface name="position">
        <param name="initial_value">0.0</param>
      </state_interface>
      <state_interface name="velocity"/>
      <state_interface name="effort"/>
    </joint>
    <joint name="joint2">
      <command_interface name="position">
        <param name="min">{-2*pi}</param>
        <param name="max">{2*pi}</param>
      </command_interface>
      <command_interface name="velocity">
        <param name="min">-3.2</param>
        <param name="max">3.2</param>
      </command_interface>
      <command_interface name="effort">
        <param name="min">-30</param>
        <param name="max">30</param>
      </command_interface>
      <state_interface name="position">
        <param name="initial_value">0.0</param>
      </state_interface>
      <state_interface name="velocity"/>
      <state_interface name="effort"/>
    </joint>
    <joint name="joint3">
      <command_interface name="position">
        <param name="min">{-2*pi}</param>
        <param name="max">{2*pi}</param>
      </command_interface>
      <command_interface name="velocity">
        <param name="min">-3.2</param>
        <param name="max">3.2</param>
      </command_interface>
      <command_interface name="effort">
        <param name="min">-30</param>
        <param name="max">30</param>
      </command_interface>
      <state_interface name="position">
        <param name="initial_value">0.0</param>
      </state_interface>
      <state_interface name="velocity"/>
      <state_interface name="effort"/>
    </joint>
    <joint name="joint4">
      <command_interface name="position">
        <param name="min">{-2*pi}</param>
        <param name="max">{2*pi}</param>
      </command_interface>
      <command_interface name="velocity">
        <param name="min">-3.2</param>
        <param name="max">3.2</param>
      </command_interface>
      <command_interface name="effort">
        <param name="min">-30</param>
        <param name="max">30</param>
      </command_interface>
      <state_interface name="position">
        <param name="initial_value">0.0</param>
      </state_interface>
      <state_interface name="velocity"/>
      <state_interface name="effort"/>
    </joint>
    <joint name="joint5">
      <command_interface name="position">
        <param name="min">{-2*pi}</param>
        <param name="max">{2*pi}</param>
      </command_interface>
      <command_interface name="velocity">
        <param name="min">-3.2</param>
        <param name="max">3.2</param>
      </command_interface>
      <command_interface name="effort">
        <param name="min">-30</param>
        <param name="max">30</param>
      </command_interface>
      <state_interface name="position">
        <param name="initial_value">0.0</param>
      </state_interface>
      <state_interface name="velocity"/>
      <state_interface name="effort"/>
    </joint>
    <joint name="joint6">
      <command_interface name="position">
        <param name="min">{-2*pi}</param>
        <param name="max">{2*pi}</param>
      </command_interface>
      <command_interface name="velocity">
        <param name="min">-3.2</param>
        <param name="max">3.2</param>
      </command_interface>
      <command_interface name="effort">
        <param name="min">-30</param>
        <param name="max">30</param>
      </command_interface>
      <state_interface name="position">
        <param name="initial_value">0.0</param>
      </state_interface>
      <state_interface name="velocity"/>
      <state_interface name="effort"/>
    </joint>
  </ros2_control>
  <gazebo>
    <!-- 必须要全部才有用 -->
    <self_collide>1</self_collide>
    <!-- 理论上可以用相对路径这个地方 -->
    <!-- <plugin filename="ign_ros2_control-system" name="ign_ros2_control::IgnitionROS2ControlPlugin">
            <parameters>/home/ccs/moveit_ws/src/z1_description/config/controller_dual.yaml</parameters>
        </plugin> -->
    <plugin filename="gz_ros2_control-system" name="gz_ros2_control::GazeboSimROS2ControlPlugin">
      <parameters>/home/ccs/test_ws/install/z1_description/share/z1_description/config/controller_single.yaml</parameters>
      <!-- <parameters>/home/ccs/moveit_ws/src/z1_description/config/controller_dual.yaml</parameters> -->
    </plugin>
    <!-- <plugin filename="gz_ros2_control-system" name="gz_ros2_control::GazeboSimROS2ControlPlugin">
            <parameters>$(find gz_ros2_control_demos)/config/cartpole_controller_effort.yaml</parameters>
        </plugin> -->
    <plugin filename="ignition-gazebo-sensors-system" name="ignition::gazebo::systems::Sensors">
        </plugin>
    <plugin filename="ignition-gazebo-forcetorque-system" name="ignition::gazebo::systems::ForceTorque">
        </plugin>
  </gazebo>
</robot>
